<?xml version="1.0" ?>
<!-- =================================================================================== -->
<!-- |    This document was autogenerated by xacro from ffw_bg2_follower.urdf.xacro    | -->
<!-- |    EDITING THIS FILE BY HAND IS NOT RECOMMENDED                                 | -->
<!-- =================================================================================== -->
<robot name="ffw_bg2_follower">
  <link name="world"/>
  <joint name="world_fixed" type="fixed">
    <parent link="world"/>
    <child link="base_link"/>
    <origin rpy="0 0 0" xyz="0.0 0.0 0.0"/>
  </joint>
  <link name="base_link">
    <visual>
      <origin rpy="0 0 0" xyz="0 0 0"/>
      <geometry>
        <mesh filename="package://ffw_description/meshes/ffw_bg2_rev4_follower/base_mobile_assy.stl" scale="0.001 0.001 0.001"/>
      </geometry>
      <material name="silver">
        <color rgba="0.75 0.75 0.75 1"/>
      </material>
    </visual>
    <collision>
      <origin rpy="0 0 0" xyz="0 0 0"/>
      <geometry>
        <mesh filename="package://ffw_description/meshes/ffw_bg2_rev4_follower/base_mobile_assy.stl" scale="0.001 0.001 0.001"/>
      </geometry>
    </collision>
  </link>
  <material name="aluminum">
    <color rgba="0.5 0.5 0.5 1"/>
  </material>
  <material name="plastic">
    <color rgba="0.1 0.1 0.1 1"/>
  </material>
  <joint name="lift_joint" type="prismatic">
    <parent link="base_link"/>
    <child link="arm_base_link"/>
    <origin rpy="0 0 0" xyz="0.0055 0 1.4316"/>
    <axis xyz="0 0 1"/>
    <limit effort="1000" lower="-0.5" upper="0.0" velocity="4.8"/>
    <dynamics damping="0.1"/>
  </joint>
  <link name="arm_base_link">
    <visual>
      <origin rpy="0 0 0" xyz="0 0 0"/>
      <geometry>
        <mesh filename="package://ffw_description/meshes/common/follower/body_arm_assy.stl" scale="0.001 0.001 0.001"/>
      </geometry>
      <material name="white">
        <color rgba="1 1 1 1"/>
      </material>
    </visual>
    <collision>
      <origin rpy="0 0 0" xyz="0 0 0"/>
      <geometry>
        <mesh filename="package://ffw_description/meshes/common/follower/body_arm_assy.stl" scale="0.001 0.001 0.001"/>
      </geometry>
    </collision>
  </link>
  <joint name="head_joint1" type="revolute">
    <parent link="arm_base_link"/>
    <child link="head_link1"/>
    <origin rpy="0 0 0" xyz="0.0494878 0 0.102123"/>
    <axis xyz="0 1 0"/>
    <limit effort="1000" lower="-0.2317" upper="0.6951" velocity="4.8"/>
    <dynamics damping="0.1"/>
  </joint>
  <link name="head_link1">
    <visual>
      <origin rpy="0 0 0" xyz="0 0 0"/>
      <geometry>
        <mesh filename="package://ffw_description/meshes/common/follower/head_link1.stl" scale="0.001 0.001 0.001"/>
      </geometry>
      <material name="grey">
        <color rgba="0.2 0.2 0.2 1"/>
      </material>
    </visual>
    <collision>
      <origin rpy="0 0 0" xyz="0 0 0"/>
      <geometry>
        <mesh filename="package://ffw_description/meshes/common/follower/head_link1.stl" scale="0.001 0.001 0.001"/>
      </geometry>
    </collision>
  </link>
  <joint name="head_joint2" type="revolute">
    <parent link="head_link1"/>
    <child link="head_link2"/>
    <origin rpy="0 0 0" xyz="0.0365694 0 0.0563797"/>
    <axis xyz="0 0 1"/>
    <limit effort="1000" lower="-0.35" upper="0.35" velocity="4.8"/>
    <dynamics damping="0.1"/>
  </joint>
  <link name="head_link2">
    <visual>
      <origin rpy="0 0 0" xyz="0 0 0"/>
      <geometry>
        <mesh filename="package://ffw_description/meshes/common/follower/head_link2.stl" scale="0.001 0.001 0.001"/>
      </geometry>
      <material name="white">
        <color rgba="1 1 1 1"/>
      </material>
    </visual>
    <collision>
      <origin rpy="0 0 0" xyz="0 0 0"/>
      <geometry>
        <mesh filename="package://ffw_description/meshes/common/follower/head_link2.stl" scale="0.001 0.001 0.001"/>
      </geometry>
    </collision>
  </link>
  <joint name="arm_l_joint1" type="revolute">
    <parent link="arm_base_link"/>
    <child link="arm_l_link1"/>
    <origin rpy="0 0 0" xyz="0 0.1045 0"/>
    <axis xyz="0 1 0"/>
    <limit effort="1000" lower="-3.14" upper="3.14" velocity="4.8"/>
    <dynamics damping="0.1"/>
  </joint>
  <link name="arm_l_link1">
    <visual>
      <origin rpy="0 0 0" xyz="0 0 0"/>
      <geometry>
        <mesh filename="package://ffw_description/meshes/common/follower/arm_l_link1.stl" scale="0.001 0.001 0.001"/>
      </geometry>
      <material name="black">
        <color rgba="0.2 0.2 0.2 1"/>
      </material>
    </visual>
    <collision>
      <origin rpy="0 0 0" xyz="0 0 0"/>
      <geometry>
        <mesh filename="package://ffw_description/meshes/common/follower/arm_l_link1.stl" scale="0.001 0.001 0.001"/>
      </geometry>
    </collision>
  </link>
  <joint name="arm_l_joint2" type="revolute">
    <parent link="arm_l_link1"/>
    <child link="arm_l_link2"/>
    <origin rpy="0 0 0" xyz="0 0.123 0"/>
    <axis xyz="1 0 0"/>
    <limit effort="1000" lower="0.0" upper="3.14" velocity="4.8"/>
    <dynamics damping="0.1"/>
  </joint>
  <link name="arm_l_link2">
    <visual>
      <origin rpy="0 0 0" xyz="0 0 0"/>
      <geometry>
        <mesh filename="package://ffw_description/meshes/common/follower/arm_l_link2.stl" scale="0.001 0.001 0.001"/>
      </geometry>
      <material name="black">
        <color rgba="0.2 0.2 0.2 1"/>
      </material>
    </visual>
    <collision>
      <origin rpy="0 0 0" xyz="0 0 0"/>
      <geometry>
        <mesh filename="package://ffw_description/meshes/common/follower/arm_l_link2.stl" scale="0.001 0.001 0.001"/>
      </geometry>
    </collision>
  </link>
  <joint name="arm_l_joint3" type="revolute">
    <parent link="arm_l_link2"/>
    <child link="arm_l_link3"/>
    <origin rpy="0 0 0" xyz="0 0 -0.165"/>
    <axis xyz="0 0 1"/>
    <limit effort="1000" lower="-3.14" upper="3.14" velocity="4.8"/>
    <dynamics damping="0.1"/>
  </joint>
  <link name="arm_l_link3">
    <visual>
      <origin rpy="0 0 0" xyz="0 0 0"/>
      <geometry>
        <mesh filename="package://ffw_description/meshes/common/follower/arm_l_link3.stl" scale="0.001 0.001 0.001"/>
      </geometry>
      <material name="black">
        <color rgba="0.2 0.2 0.2 1"/>
      </material>
    </visual>
    <collision>
      <origin rpy="0 0 0" xyz="0 0 0"/>
      <geometry>
        <mesh filename="package://ffw_description/meshes/common/follower/arm_l_link3.stl" scale="0.001 0.001 0.001"/>
      </geometry>
    </collision>
  </link>
  <joint name="arm_l_joint4" type="revolute">
    <parent link="arm_l_link3"/>
    <child link="arm_l_link4"/>
    <origin rpy="0 0 0" xyz="0.041004 0 -0.135"/>
    <axis xyz="0 1 0"/>
    <limit effort="1000" lower="-2.9361" upper="1.0786" velocity="4.8"/>
    <dynamics damping="0.1"/>
  </joint>
  <link name="arm_l_link4">
    <visual>
      <origin rpy="0 0 0" xyz="0 0 0"/>
      <geometry>
        <mesh filename="package://ffw_description/meshes/common/follower/arm_l_link4.stl" scale="0.001 0.001 0.001"/>
      </geometry>
      <material name="black">
        <color rgba="0.2 0.2 0.2 1"/>
      </material>
    </visual>
    <collision>
      <origin rpy="0 0 0" xyz="0 0 0"/>
      <geometry>
        <mesh filename="package://ffw_description/meshes/common/follower/arm_l_link4.stl" scale="0.001 0.001 0.001"/>
      </geometry>
    </collision>
  </link>
  <joint name="arm_l_joint5" type="revolute">
    <parent link="arm_l_link4"/>
    <child link="arm_l_link5"/>
    <origin rpy="0 0 0" xyz="-0.041004 0 -0.1489"/>
    <axis xyz="0 0 1"/>
    <limit effort="1000" lower="-3.14" upper="3.14" velocity="4.8"/>
    <dynamics damping="0.1"/>
  </joint>
  <link name="arm_l_link5">
    <visual>
      <origin rpy="0 0 0" xyz="0 0 0"/>
      <geometry>
        <mesh filename="package://ffw_description/meshes/common/follower/arm_l_link5.stl" scale="0.001 0.001 0.001"/>
      </geometry>
      <material name="black">
        <color rgba="0.2 0.2 0.2 1"/>
      </material>
    </visual>
    <collision>
      <origin rpy="0 0 0" xyz="0 0 0"/>
      <geometry>
        <mesh filename="package://ffw_description/meshes/common/follower/arm_l_link5.stl" scale="0.001 0.001 0.001"/>
      </geometry>
    </collision>
  </link>
  <joint name="arm_l_joint6" type="revolute">
    <parent link="arm_l_link5"/>
    <child link="arm_l_link6"/>
    <origin rpy="0 0 0" xyz="0 0 -0.1041"/>
    <axis xyz="0 1 0"/>
    <limit effort="1000" lower="-1.57" upper="1.57" velocity="4.8"/>
    <dynamics damping="0.1"/>
  </joint>
  <link name="arm_l_link6">
    <visual>
      <origin rpy="0 0 0" xyz="0 0 0"/>
      <geometry>
        <mesh filename="package://ffw_description/meshes/common/follower/arm_l_link6.stl" scale="0.001 0.001 0.001"/>
      </geometry>
      <material name="black">
        <color rgba="0.2 0.2 0.2 1"/>
      </material>
    </visual>
    <collision>
      <origin rpy="0 0 0" xyz="0 0 0"/>
      <geometry>
        <mesh filename="package://ffw_description/meshes/common/follower/arm_l_link6.stl" scale="0.001 0.001 0.001"/>
      </geometry>
    </collision>
  </link>
  <joint name="arm_l_joint7" type="revolute">
    <parent link="arm_l_link6"/>
    <child link="arm_l_link7"/>
    <origin rpy="0 0 0" xyz="0 0 -0.0885"/>
    <axis xyz="1 0 0"/>
    <limit effort="1000" lower="-1.8201" upper="1.5804" velocity="4.8"/>
    <dynamics damping="0.1"/>
  </joint>
  <link name="arm_l_link7">
    <visual>
      <origin rpy="0 0 0" xyz="0 0 0"/>
      <geometry>
        <mesh filename="package://ffw_description/meshes/common/follower/arm_l_link7.stl" scale="0.001 0.001 0.001"/>
      </geometry>
      <material name="black">
        <color rgba="0.2 0.2 0.2 1"/>
      </material>
    </visual>
    <collision>
      <origin rpy="0 0 0" xyz="0 0 0"/>
      <geometry>
        <mesh filename="package://ffw_description/meshes/common/follower/arm_l_link7.stl" scale="0.001 0.001 0.001"/>
      </geometry>
    </collision>
  </link>
  <!-- camera body, with origin at bottom screw mount -->
  <joint name="camera_l_joint" type="fixed">
    <origin rpy="-1.57079632679 1.66678943569 0" xyz="0.108236 -0.021 -0.062552"/>
    <parent link="arm_l_link7"/>
    <child link="camera_l_bottom_screw_frame"/>
  </joint>
  <link name="camera_l_bottom_screw_frame"/>
  <joint name="camera_l_link_joint" type="fixed">
    <origin rpy="0 0 0" xyz="0.01085 0.009 0.021"/>
    <parent link="camera_l_bottom_screw_frame"/>
    <child link="camera_l_link"/>
  </joint>
  <link name="camera_l_link">
    <visual>
      <!-- the mesh origin is at front plate in between the two infrared camera axes -->
      <origin rpy="1.5707963267948966 0 1.5707963267948966" xyz="0.0038 -0.009 0"/>
      <geometry>
        <mesh filename="package://realsense2_description/meshes/d405.stl" scale="0.001 0.001 0.001"/>
      </geometry>
      <material name="aluminum"/>
    </visual>
    <collision>
      <origin rpy="0 0 0" xyz="-0.0078 -0.009 0"/>
      <geometry>
        <box size="0.023 0.042 0.042"/>
      </geometry>
    </collision>
    <inertial>
      <!-- The following are not reliable values, and should not be used for modeling -->
      <mass value="0.072"/>
      <origin xyz="0 0 0"/>
      <inertia ixx="0.003881243" ixy="0.0" ixz="0.0" iyy="0.000498940" iyz="0.0" izz="0.003879257"/>
    </inertial>
  </link>
  <joint name="arm_r_joint1" type="revolute">
    <parent link="arm_base_link"/>
    <child link="arm_r_link1"/>
    <origin rpy="0 0 0" xyz="0 -0.1045 0"/>
    <axis xyz="0 1 0"/>
    <limit effort="1000" lower="-3.14" upper="3.14" velocity="4.8"/>
    <dynamics damping="0.1"/>
  </joint>
  <link name="arm_r_link1">
    <visual>
      <origin rpy="0 0 0" xyz="0 0 0"/>
      <geometry>
        <mesh filename="package://ffw_description/meshes/common/follower/arm_r_link1.stl" scale="0.001 0.001 0.001"/>
      </geometry>
      <material name="black">
        <color rgba="0.2 0.2 0.2 1"/>
      </material>
    </visual>
    <collision>
      <origin rpy="0 0 0" xyz="0 0 0"/>
      <geometry>
        <mesh filename="package://ffw_description/meshes/common/follower/arm_r_link1.stl" scale="0.001 0.001 0.001"/>
      </geometry>
    </collision>
  </link>
  <joint name="arm_r_joint2" type="revolute">
    <parent link="arm_r_link1"/>
    <child link="arm_r_link2"/>
    <origin rpy="0 0 0" xyz="0 -0.123 0"/>
    <axis xyz="1 0 0"/>
    <limit effort="1000" lower="-3.14" upper="0" velocity="4.8"/>
    <dynamics damping="0.1"/>
  </joint>
  <link name="arm_r_link2">
    <visual>
      <origin rpy="0 0 0" xyz="0 0 0"/>
      <geometry>
        <mesh filename="package://ffw_description/meshes/common/follower/arm_r_link2.stl" scale="0.001 0.001 0.001"/>
      </geometry>
      <material name="black">
        <color rgba="0.2 0.2 0.2 1"/>
      </material>
    </visual>
    <collision>
      <origin rpy="0 0 0" xyz="0 0 0"/>
      <geometry>
        <mesh filename="package://ffw_description/meshes/common/follower/arm_r_link2.stl" scale="0.001 0.001 0.001"/>
      </geometry>
    </collision>
  </link>
  <joint name="arm_r_joint3" type="revolute">
    <parent link="arm_r_link2"/>
    <child link="arm_r_link3"/>
    <origin rpy="0 0 0" xyz="0 0 -0.165"/>
    <axis xyz="0 0 1"/>
    <limit effort="1000" lower="-3.14" upper="3.14" velocity="4.8"/>
    <dynamics damping="0.1"/>
  </joint>
  <link name="arm_r_link3">
    <visual>
      <origin rpy="0 0 0" xyz="0 0 0"/>
      <geometry>
        <mesh filename="package://ffw_description/meshes/common/follower/arm_r_link3.stl" scale="0.001 0.001 0.001"/>
      </geometry>
      <material name="black">
        <color rgba="0.2 0.2 0.2 1"/>
      </material>
    </visual>
    <collision>
      <origin rpy="0 0 0" xyz="0 0 0"/>
      <geometry>
        <mesh filename="package://ffw_description/meshes/common/follower/arm_r_link3.stl" scale="0.001 0.001 0.001"/>
      </geometry>
    </collision>
  </link>
  <joint name="arm_r_joint4" type="revolute">
    <parent link="arm_r_link3"/>
    <child link="arm_r_link4"/>
    <origin rpy="0 0 0" xyz="0.041004 0 -0.135"/>
    <axis xyz="0 1 0"/>
    <limit effort="1000" lower="-2.9361" upper="1.0786" velocity="4.8"/>
    <dynamics damping="0.1"/>
  </joint>
  <link name="arm_r_link4">
    <visual>
      <origin rpy="0 0 0" xyz="0 0 0"/>
      <geometry>
        <mesh filename="package://ffw_description/meshes/common/follower/arm_r_link4.stl" scale="0.001 0.001 0.001"/>
      </geometry>
      <material name="black">
        <color rgba="0.2 0.2 0.2 1"/>
      </material>
    </visual>
    <collision>
      <origin rpy="0 0 0" xyz="0 0 0"/>
      <geometry>
        <mesh filename="package://ffw_description/meshes/common/follower/arm_r_link4.stl" scale="0.001 0.001 0.001"/>
      </geometry>
    </collision>
  </link>
  <joint name="arm_r_joint5" type="revolute">
    <parent link="arm_r_link4"/>
    <child link="arm_r_link5"/>
    <origin rpy="0 0 0" xyz="-0.041004 0 -0.1489"/>
    <axis xyz="0 0 1"/>
    <limit effort="1000" lower="-3.14" upper="3.14" velocity="4.8"/>
    <dynamics damping="0.1"/>
  </joint>
  <link name="arm_r_link5">
    <visual>
      <origin rpy="0 0 0" xyz="0 0 0"/>
      <geometry>
        <mesh filename="package://ffw_description/meshes/common/follower/arm_r_link5.stl" scale="0.001 0.001 0.001"/>
      </geometry>
      <material name="black">
        <color rgba="0.2 0.2 0.2 1"/>
      </material>
    </visual>
    <collision>
      <origin rpy="0 0 0" xyz="0 0 0"/>
      <geometry>
        <mesh filename="package://ffw_description/meshes/common/follower/arm_r_link5.stl" scale="0.001 0.001 0.001"/>
      </geometry>
    </collision>
  </link>
  <joint name="arm_r_joint6" type="revolute">
    <parent link="arm_r_link5"/>
    <child link="arm_r_link6"/>
    <origin rpy="0 0 0" xyz="0 0 -0.1041"/>
    <axis xyz="0 1 0"/>
    <limit effort="1000" lower="-1.57" upper="1.57" velocity="4.8"/>
    <dynamics damping="0.1"/>
  </joint>
  <link name="arm_r_link6">
    <visual>
      <origin rpy="0 0 0" xyz="0 0 0"/>
      <geometry>
        <mesh filename="package://ffw_description/meshes/common/follower/arm_r_link6.stl" scale="0.001 0.001 0.001"/>
      </geometry>
      <material name="black">
        <color rgba="0.2 0.2 0.2 1"/>
      </material>
    </visual>
    <collision>
      <origin rpy="0 0 0" xyz="0 0 0"/>
      <geometry>
        <mesh filename="package://ffw_description/meshes/common/follower/arm_r_link6.stl" scale="0.001 0.001 0.001"/>
      </geometry>
    </collision>
  </link>
  <joint name="arm_r_joint7" type="revolute">
    <parent link="arm_r_link6"/>
    <child link="arm_r_link7"/>
    <origin rpy="0 0 0" xyz="0 0 -0.0885"/>
    <axis xyz="1 0 0"/>
    <limit effort="1000" lower="-1.5804" upper="1.8201" velocity="4.8"/>
    <dynamics damping="0.1"/>
  </joint>
  <link name="arm_r_link7">
    <visual>
      <origin rpy="0 0 0" xyz="0 0 0"/>
      <geometry>
        <mesh filename="package://ffw_description/meshes/common/follower/arm_r_link7.stl" scale="0.001 0.001 0.001"/>
      </geometry>
      <material name="black">
        <color rgba="0.2 0.2 0.2 1"/>
      </material>
    </visual>
    <collision>
      <origin rpy="0 0 0" xyz="0 0 0"/>
      <geometry>
        <mesh filename="package://ffw_description/meshes/common/follower/arm_r_link7.stl" scale="0.001 0.001 0.001"/>
      </geometry>
    </collision>
  </link>
  <!-- camera body, with origin at bottom screw mount -->
  <joint name="camera_r_joint" type="fixed">
    <origin rpy="-1.57079632679 1.66678943569 0" xyz="0.108236 -0.021 -0.062552"/>
    <parent link="arm_r_link7"/>
    <child link="camera_r_bottom_screw_frame"/>
  </joint>
  <link name="camera_r_bottom_screw_frame"/>
  <joint name="camera_r_link_joint" type="fixed">
    <origin rpy="0 0 0" xyz="0.01085 0.009 0.021"/>
    <parent link="camera_r_bottom_screw_frame"/>
    <child link="camera_r_link"/>
  </joint>
  <link name="camera_r_link">
    <visual>
      <!-- the mesh origin is at front plate in between the two infrared camera axes -->
      <origin rpy="1.5707963267948966 0 1.5707963267948966" xyz="0.0038 -0.009 0"/>
      <geometry>
        <mesh filename="package://realsense2_description/meshes/d405.stl" scale="0.001 0.001 0.001"/>
      </geometry>
      <material name="aluminum"/>
    </visual>
    <collision>
      <origin rpy="0 0 0" xyz="-0.0078 -0.009 0"/>
      <geometry>
        <box size="0.023 0.042 0.042"/>
      </geometry>
    </collision>
    <inertial>
      <!-- The following are not reliable values, and should not be used for modeling -->
      <mass value="0.072"/>
      <origin xyz="0 0 0"/>
      <inertia ixx="0.003881243" ixy="0.0" ixz="0.0" iyy="0.000498940" iyz="0.0" izz="0.003879257"/>
    </inertial>
  </link>
  <joint name="gripper_l_joint" type="fixed">
    <origin rpy="0 3.14159265359 0" xyz="0 0 -0.078"/>
    <parent link="arm_l_link7"/>
    <child link="gripper_l_rh_p12_rn_base"/>
  </joint>
  <!-- base -->
  <link name="gripper_l_rh_p12_rn_base">
    <collision>
      <origin rpy="0 0 0" xyz="0 0 0"/>
      <geometry>
        <mesh filename="package://ffw_description/meshes/common/rh_p12_rn_a/base.stl" scale="0.001 0.001 0.001"/>
      </geometry>
    </collision>
    <visual>
      <origin rpy="0 0 0" xyz="0 0 0"/>
      <geometry>
        <mesh filename="package://ffw_description/meshes/common/rh_p12_rn_a/base.stl" scale="0.001 0.001 0.001"/>
      </geometry>
      <material name="grey">
        <color rgba="0.2 0.2 0.2 1"/>
      </material>
    </visual>
    <inertial>
      <origin rpy="0 0 0" xyz="0.000 0.000 0.032"/>
      <mass value="0.236"/>
      <inertia ixx="0.000001" ixy="0.0" ixz="0.0" iyy="0.000001" iyz="0.0" izz="0.000001"/>
    </inertial>
  </link>
  <!-- Joint -->
  <joint name="gripper_l_joint1" type="revolute">
    <parent link="gripper_l_rh_p12_rn_base"/>
    <child link="gripper_l_rh_p12_rn_r1"/>
    <origin rpy="0 0 0" xyz="0.0 0.008 0.048"/>
    <axis xyz="1 0 0"/>
    <limit effort="1000" lower="0.0" upper="1.1" velocity="6.5"/>
    <dynamics damping="0.7"/>
  </joint>
  <!-- rh_p12_rn_r1 -->
  <link name="gripper_l_rh_p12_rn_r1">
    <collision>
      <origin rpy="0 0 0" xyz="0 0 0"/>
      <geometry>
        <mesh filename="package://ffw_description/meshes/common/rh_p12_rn_a/r1.stl" scale="0.001 0.001 0.001"/>
      </geometry>
    </collision>
    <visual>
      <origin rpy="0 0 0" xyz="0 0 0"/>
      <geometry>
        <mesh filename="package://ffw_description/meshes/common/rh_p12_rn_a/r1.stl" scale="0.001 0.001 0.001"/>
      </geometry>
      <material name="grey">
        <color rgba="0.2 0.2 0.2 1"/>
      </material>
    </visual>
    <inertial>
      <origin rpy="0 0 0" xyz="0.000 0.034 0.004"/>
      <mass value="0.068"/>
      <inertia ixx="0.000001" ixy="0.0" ixz="0.0" iyy="0.000001" iyz="0.0" izz="0.000001"/>
    </inertial>
  </link>
  <!-- Right Joint 2 -->
  <joint name="gripper_l_joint2" type="revolute">
    <parent link="gripper_l_rh_p12_rn_r1"/>
    <child link="gripper_l_rh_p12_rn_r2"/>
    <origin rpy="0 0 0" xyz="0.0 0.0493634 0.0285"/>
    <axis xyz="-1 0 0"/>
    <limit effort="1000" lower="0.0" upper="1.0" velocity="6.5"/>
    <dynamics damping="0.7"/>
    <mimic joint="gripper_l_joint1" multiplier="1"/>
  </joint>
  <!-- rh_p12_rn_r2 -->
  <link name="gripper_l_rh_p12_rn_r2">
    <collision>
      <origin rpy="0 0 0" xyz="0 0 0"/>
      <geometry>
        <mesh filename="package://ffw_description/meshes/common/rh_p12_rn_a/r2.stl" scale="0.001 0.001 0.001"/>
      </geometry>
    </collision>
    <visual>
      <origin rpy="0 0 0" xyz="0 0 0"/>
      <geometry>
        <mesh filename="package://ffw_description/meshes/common/rh_p12_rn_a/r2.stl" scale="0.001 0.001 0.001"/>
      </geometry>
      <material name="grey">
        <color rgba="0.2 0.2 0.2 1"/>
      </material>
    </visual>
    <inertial>
      <origin rpy="0 0 0" xyz="0.000 0.006 0.011"/>
      <mass value="0.022"/>
      <inertia ixx="0.000001" ixy="0.0" ixz="0.0" iyy="0.000001" iyz="0.0" izz="0.000001"/>
    </inertial>
  </link>
  <!-- Left Joint 1 -->
  <joint name="gripper_l_joint3" type="revolute">
    <parent link="gripper_l_rh_p12_rn_base"/>
    <child link="gripper_l_rh_p12_rn_l1"/>
    <origin rpy="0 0 0" xyz="0.0 -0.008 0.048"/>
    <axis xyz="-1 0 0"/>
    <limit effort="1000" lower="0.0" upper="1.1" velocity="6.5"/>
    <dynamics damping="0.7"/>
    <mimic joint="gripper_l_joint1" multiplier="1"/>
  </joint>
  <!-- rh_p12_rn_l1 -->
  <link name="gripper_l_rh_p12_rn_l1">
    <collision>
      <origin rpy="0 0 0" xyz="0 0 0"/>
      <geometry>
        <mesh filename="package://ffw_description/meshes/common/rh_p12_rn_a/l1.stl" scale="0.001 0.001 0.001"/>
      </geometry>
    </collision>
    <visual>
      <origin rpy="0 0 0" xyz="0 0 0"/>
      <geometry>
        <mesh filename="package://ffw_description/meshes/common/rh_p12_rn_a/l1.stl" scale="0.001 0.001 0.001"/>
      </geometry>
      <material name="grey">
        <color rgba="0.2 0.2 0.2 1"/>
      </material>
    </visual>
    <inertial>
      <origin rpy="0 0 0" xyz="0.000 -0.034 0.004"/>
      <mass value="0.068"/>
      <inertia ixx="0.000001" ixy="0.0" ixz="0.0" iyy="0.000001" iyz="0.0" izz="0.000001"/>
    </inertial>
  </link>
  <!-- Left Joint 2 -->
  <joint name="gripper_l_joint4" type="revolute">
    <parent link="gripper_l_rh_p12_rn_l1"/>
    <child link="gripper_l_rh_p12_rn_l2"/>
    <origin rpy="0 0 0" xyz="0.0 -0.0493634 0.0285"/>
    <axis xyz="1 0 0"/>
    <limit effort="1000" lower="0.0" upper="1.0" velocity="6.5"/>
    <dynamics damping="0.7"/>
    <mimic joint="gripper_l_joint1" multiplier="1"/>
  </joint>
  <!-- rh_p12_rn_l2 -->
  <link name="gripper_l_rh_p12_rn_l2">
    <collision>
      <origin rpy="0 0 0" xyz="0 0 0"/>
      <geometry>
        <mesh filename="package://ffw_description/meshes/common/rh_p12_rn_a/l2.stl" scale="0.001 0.001 0.001"/>
      </geometry>
    </collision>
    <visual>
      <origin rpy="0 0 0" xyz="0 0 0"/>
      <geometry>
        <mesh filename="package://ffw_description/meshes/common/rh_p12_rn_a/l2.stl" scale="0.001 0.001 0.001"/>
      </geometry>
      <material name="grey">
        <color rgba="0.2 0.2 0.2 1"/>
      </material>
    </visual>
    <inertial>
      <origin rpy="0 0 0" xyz="0.000 -0.006 0.011"/>
      <mass value="0.022"/>
      <inertia ixx="0.000001" ixy="0.0" ixz="0.0" iyy="0.000001" iyz="0.0" izz="0.000001"/>
    </inertial>
  </link>
  <joint name="gripper_r_joint" type="fixed">
    <origin rpy="0 3.14159265359 0" xyz="0 0 -0.078"/>
    <parent link="arm_r_link7"/>
    <child link="gripper_r_rh_p12_rn_base"/>
  </joint>
  <!-- base -->
  <link name="gripper_r_rh_p12_rn_base">
    <collision>
      <origin rpy="0 0 0" xyz="0 0 0"/>
      <geometry>
        <mesh filename="package://ffw_description/meshes/common/rh_p12_rn_a/base.stl" scale="0.001 0.001 0.001"/>
      </geometry>
    </collision>
    <visual>
      <origin rpy="0 0 0" xyz="0 0 0"/>
      <geometry>
        <mesh filename="package://ffw_description/meshes/common/rh_p12_rn_a/base.stl" scale="0.001 0.001 0.001"/>
      </geometry>
      <material name="grey">
        <color rgba="0.2 0.2 0.2 1"/>
      </material>
    </visual>
    <inertial>
      <origin rpy="0 0 0" xyz="0.000 0.000 0.032"/>
      <mass value="0.236"/>
      <inertia ixx="0.000001" ixy="0.0" ixz="0.0" iyy="0.000001" iyz="0.0" izz="0.000001"/>
    </inertial>
  </link>
  <!-- Joint -->
  <joint name="gripper_r_joint1" type="revolute">
    <parent link="gripper_r_rh_p12_rn_base"/>
    <child link="gripper_r_rh_p12_rn_r1"/>
    <origin rpy="0 0 0" xyz="0.0 0.008 0.048"/>
    <axis xyz="1 0 0"/>
    <limit effort="1000" lower="0.0" upper="1.1" velocity="6.5"/>
    <dynamics damping="0.7"/>
  </joint>
  <!-- rh_p12_rn_r1 -->
  <link name="gripper_r_rh_p12_rn_r1">
    <collision>
      <origin rpy="0 0 0" xyz="0 0 0"/>
      <geometry>
        <mesh filename="package://ffw_description/meshes/common/rh_p12_rn_a/r1.stl" scale="0.001 0.001 0.001"/>
      </geometry>
    </collision>
    <visual>
      <origin rpy="0 0 0" xyz="0 0 0"/>
      <geometry>
        <mesh filename="package://ffw_description/meshes/common/rh_p12_rn_a/r1.stl" scale="0.001 0.001 0.001"/>
      </geometry>
      <material name="grey">
        <color rgba="0.2 0.2 0.2 1"/>
      </material>
    </visual>
    <inertial>
      <origin rpy="0 0 0" xyz="0.000 0.034 0.004"/>
      <mass value="0.068"/>
      <inertia ixx="0.000001" ixy="0.0" ixz="0.0" iyy="0.000001" iyz="0.0" izz="0.000001"/>
    </inertial>
  </link>
  <!-- Right Joint 2 -->
  <joint name="gripper_r_joint2" type="revolute">
    <parent link="gripper_r_rh_p12_rn_r1"/>
    <child link="gripper_r_rh_p12_rn_r2"/>
    <origin rpy="0 0 0" xyz="0.0 0.0493634 0.0285"/>
    <axis xyz="-1 0 0"/>
    <limit effort="1000" lower="0.0" upper="1.0" velocity="6.5"/>
    <dynamics damping="0.7"/>
    <mimic joint="gripper_r_joint1" multiplier="1"/>
  </joint>
  <!-- rh_p12_rn_r2 -->
  <link name="gripper_r_rh_p12_rn_r2">
    <collision>
      <origin rpy="0 0 0" xyz="0 0 0"/>
      <geometry>
        <mesh filename="package://ffw_description/meshes/common/rh_p12_rn_a/r2.stl" scale="0.001 0.001 0.001"/>
      </geometry>
    </collision>
    <visual>
      <origin rpy="0 0 0" xyz="0 0 0"/>
      <geometry>
        <mesh filename="package://ffw_description/meshes/common/rh_p12_rn_a/r2.stl" scale="0.001 0.001 0.001"/>
      </geometry>
      <material name="grey">
        <color rgba="0.2 0.2 0.2 1"/>
      </material>
    </visual>
    <inertial>
      <origin rpy="0 0 0" xyz="0.000 0.006 0.011"/>
      <mass value="0.022"/>
      <inertia ixx="0.000001" ixy="0.0" ixz="0.0" iyy="0.000001" iyz="0.0" izz="0.000001"/>
    </inertial>
  </link>
  <!-- Left Joint 1 -->
  <joint name="gripper_r_joint3" type="revolute">
    <parent link="gripper_r_rh_p12_rn_base"/>
    <child link="gripper_r_rh_p12_rn_l1"/>
    <origin rpy="0 0 0" xyz="0.0 -0.008 0.048"/>
    <axis xyz="-1 0 0"/>
    <limit effort="1000" lower="0.0" upper="1.1" velocity="6.5"/>
    <dynamics damping="0.7"/>
    <mimic joint="gripper_r_joint1" multiplier="1"/>
  </joint>
  <!-- rh_p12_rn_l1 -->
  <link name="gripper_r_rh_p12_rn_l1">
    <collision>
      <origin rpy="0 0 0" xyz="0 0 0"/>
      <geometry>
        <mesh filename="package://ffw_description/meshes/common/rh_p12_rn_a/l1.stl" scale="0.001 0.001 0.001"/>
      </geometry>
    </collision>
    <visual>
      <origin rpy="0 0 0" xyz="0 0 0"/>
      <geometry>
        <mesh filename="package://ffw_description/meshes/common/rh_p12_rn_a/l1.stl" scale="0.001 0.001 0.001"/>
      </geometry>
      <material name="grey">
        <color rgba="0.2 0.2 0.2 1"/>
      </material>
    </visual>
    <inertial>
      <origin rpy="0 0 0" xyz="0.000 -0.034 0.004"/>
      <mass value="0.068"/>
      <inertia ixx="0.000001" ixy="0.0" ixz="0.0" iyy="0.000001" iyz="0.0" izz="0.000001"/>
    </inertial>
  </link>
  <!-- Left Joint 2 -->
  <joint name="gripper_r_joint4" type="revolute">
    <parent link="gripper_r_rh_p12_rn_l1"/>
    <child link="gripper_r_rh_p12_rn_l2"/>
    <origin rpy="0 0 0" xyz="0.0 -0.0493634 0.0285"/>
    <axis xyz="1 0 0"/>
    <limit effort="1000" lower="0.0" upper="1.0" velocity="6.5"/>
    <dynamics damping="0.7"/>
    <mimic joint="gripper_r_joint1" multiplier="1"/>
  </joint>
  <!-- rh_p12_rn_l2 -->
  <link name="gripper_r_rh_p12_rn_l2">
    <collision>
      <origin rpy="0 0 0" xyz="0 0 0"/>
      <geometry>
        <mesh filename="package://ffw_description/meshes/common/rh_p12_rn_a/l2.stl" scale="0.001 0.001 0.001"/>
      </geometry>
    </collision>
    <visual>
      <origin rpy="0 0 0" xyz="0 0 0"/>
      <geometry>
        <mesh filename="package://ffw_description/meshes/common/rh_p12_rn_a/l2.stl" scale="0.001 0.001 0.001"/>
      </geometry>
      <material name="grey">
        <color rgba="0.2 0.2 0.2 1"/>
      </material>
    </visual>
    <inertial>
      <origin rpy="0 0 0" xyz="0.000 -0.006 0.011"/>
      <mass value="0.022"/>
      <inertia ixx="0.000001" ixy="0.0" ixz="0.0" iyy="0.000001" iyz="0.0" izz="0.000001"/>
    </inertial>
  </link>
</robot>
