<?xml version="1.0"?>
<robot xmlns:xacro="http://www.ros.org/wiki/xacro" name="ffw_sg2_follower">
  <xacro:property name="meshes_file_direction" value="package://ffw_description/meshes/$(arg model)" />
  <xacro:arg name="use_sim" default="false" />
  <xacro:arg name="use_fake_hardware" default="false" />
  <xacro:arg name="fake_sensor_commands" default="false" />
  <xacro:arg name="prefix" default="" />
  <xacro:arg name="model" default="ffw_sg2_rev1_follower" />

  <xacro:include filename="$(find ffw_description)/urdf/common/follower/ffw_follower_body.xacro" />

  <xacro:include filename="$(find ffw_description)/urdf/common/rh_p12_rn_a/rh_p12_rn_a.urdf.xacro" />

  <xacro:include filename="$(find ffw_description)/ros2_control/$(arg model)/ffw_sg2_follower.ros2_control.xacro" />
  <xacro:include filename="$(find ffw_description)/ros2_control/$(arg model)/ffw_sg2_base.ros2_control.xacro" />
  <xacro:include filename="$(find ffw_description)/ros2_control/$(arg model)/ffw_sg2_sensor.ros2_control.xacro" />

  <xacro:include filename="$(find ffw_description)/gazebo/$(arg model)/ffw_sg2_follower.gazebo.xacro" />

  <link name="$(arg prefix)base_link">
    <visual>
      <origin xyz="0 0 0" rpy="0 0 0" />
      <geometry>
        <mesh filename="${meshes_file_direction}/base_mobile_assy.stl" scale="0.001 0.001 0.001" />
      </geometry>
      <material name="silver">
        <color rgba="0.75 0.75 0.75 1"/>
      </material>
    </visual>
    <collision>
      <origin xyz="0 0 0" rpy="0 0 0" />
      <geometry>
        <mesh filename="${meshes_file_direction}/base_mobile_assy.stl" scale="0.001 0.001 0.001" />
      </geometry>
    </collision>
    <inertial>
       <origin xyz="-4.574796400e-02 6.581058800e-03 1.943184200e-01" />
       <mass value="3.598943900e+01" />
       <inertia ixx="1.725473500e+04" ixy="6.471795500e-02" ixz="1.890204600e-01"
       iyy="3.983747500e+04" iyz="1.716567300e-01"
       izz="2.846139500e+04" />
    </inertial>
  </link>

  <link name="$(arg prefix)lift_link">
    <visual>
      <origin xyz="0 0 0" rpy="0 0 0" />
      <geometry>
        <mesh filename="${meshes_file_direction}/lift_link.stl" scale="0.001 0.001 0.001" />
      </geometry>
      <material name="silver">
        <color rgba="0.75 0.75 0.75 1"/>
      </material>
    </visual>
    <collision>
      <origin xyz="0 0 0" rpy="0 0 0" />
      <geometry>
        <mesh filename="${meshes_file_direction}/lift_link.stl" scale="0.001 0.001 0.001" />
      </geometry>
    </collision>
    <inertial>
       <origin xyz="-1.286987800e-01 -1.604580800e-05 8.945601700e-01" />
       <mass value="1.790000000e+01" />
       <inertia ixx="1.009479700e+04" ixy="-3.568141800e-02" ixz="1.213165300e+03"
       iyy="1.027057300e+04" iyz="7.021994000e-02"
       izz="1.971602000e+02" />
    </inertial>
  </link>
  <joint name="$(arg prefix)lift_fixed_joint" type="fixed">
    <parent link="$(arg prefix)base_link"/>
    <child link="$(arg prefix)lift_link"/>
    <origin xyz="0.0 0.0 0.0" rpy="0 0 0"/>
  </joint>

  <xacro:ffw_follower_body parent="$(arg prefix)base_link" prefix="$(arg prefix)">
    <origin xyz="-0.0199 0 1.4316" rpy="0 0 0" />
  </xacro:ffw_follower_body>

  <xacro:rh_p12_rn_a parent="$(arg prefix)arm_l_link7" prefix="$(arg prefix)gripper_l_">
    <origin xyz="0 0 -0.078" rpy="0 3.14159265359 3.14159265359"/>
  </xacro:rh_p12_rn_a>

  <xacro:rh_p12_rn_a parent="$(arg prefix)arm_r_link7" prefix="$(arg prefix)gripper_r_">
    <origin xyz="0 0 -0.078" rpy="0 3.14159265359 3.14159265359"/>
  </xacro:rh_p12_rn_a>

  <joint name="$(arg prefix)left_wheel_steer" type="revolute">
      <parent link="$(arg prefix)base_link"/>
      <child link="$(arg prefix)left_wheel_steer_link"/>
      <origin xyz="0.1371 0.2554 0.27555" rpy="0 0 0"/>
      <axis xyz="0 0 1" />
      <limit velocity="9999.0" effort="9999.0" lower="${-pi*6.0}" upper="${pi*6.0}" />
  </joint>
  <link name="$(arg prefix)left_wheel_steer_link">
    <visual>
      <origin xyz="0 0 0" rpy="0 0 0" />
      <geometry>
        <mesh filename="${meshes_file_direction}/left_wheel_steer_link.stl" scale="0.001 0.001 0.001" />
      </geometry>
      <material name="silver">
        <color rgba="0.75 0.75 0.75 1"/>
      </material>
    </visual>
    <collision>
      <origin xyz="0 0 0" rpy="0 0 0" />
      <geometry>
        <mesh filename="${meshes_file_direction}/left_wheel_steer_link.stl" scale="0.001 0.001 0.001" />
      </geometry>
    </collision>
    <inertial>
       <origin xyz="9.802769300e-03 -5.471240900e-02 -1.376533800e-01" />
       <mass value="7.550951000e-01" />
       <inertia ixx="2.797326600e-03" ixy="-3.290807800e-05" ixz="-1.950671800e-04"
       iyy="3.582264900e-03" iyz="-2.853290700e-04"
       izz="1.683594000e-03" />
    </inertial>
  </link>
  <joint name="$(arg prefix)left_wheel_drive" type="continuous">
      <parent link="$(arg prefix)left_wheel_steer_link"/>
      <child link="$(arg prefix)left_wheel_drive_link"/>
      <origin xyz="0 0 -0.18905" rpy="0 0 0"/>
      <axis xyz="0 1 0" />
      <limit velocity="9999.0" effort="9999.0"/>
  </joint>
  <link name="$(arg prefix)left_wheel_drive_link">
    <visual>
      <origin xyz="0 0 0" rpy="0 0 0" />
      <geometry>
        <mesh filename="${meshes_file_direction}/left_wheel_drive_link.stl" scale="0.001 0.001 0.001" />
      </geometry>
      <material name="silver">
        <color rgba="0.75 0.75 0.75 1"/>
      </material>
    </visual>
    <collision>
      <origin xyz="0 0 0" rpy="0 0 0" />
      <geometry>
        <mesh filename="${meshes_file_direction}/left_wheel_drive_link.stl" scale="0.001 0.001 0.001" />
      </geometry>
    </collision>
    <inertial>
       <origin xyz="0.000000000e+00 -1.499601700e-03 0.000000000e+00" />
       <mass value="3.795460500e+00" />
       <inertia ixx="7.187881500e-03" ixy="0.000000000e+00" ixz="0.000000000e+00"
       iyy="1.156399900e-02" iyz="0.000000000e+00"
       izz="7.187977000e-03" />
    </inertial>
  </link>

  <joint name="$(arg prefix)right_wheel_steer" type="revolute">
      <parent link="$(arg prefix)base_link"/>
      <child link="$(arg prefix)right_wheel_steer_link"/>
      <origin xyz="0.1371 -0.2554 0.27555" rpy="0 0 0"/>
      <axis xyz="0 0 1" />
      <limit velocity="9999.0" effort="9999.0" lower="${-pi*6.0}" upper="${pi*6.0}" />
  </joint>
  <link name="$(arg prefix)right_wheel_steer_link">
    <visual>
      <origin xyz="0 0 0" rpy="0 0 0" />
      <geometry>
        <mesh filename="${meshes_file_direction}/right_wheel_steer_link.stl" scale="0.001 0.001 0.001" />
      </geometry>
      <material name="silver">
        <color rgba="0.75 0.75 0.75 1"/>
      </material>
    </visual>
    <collision>
      <origin xyz="0 0 0" rpy="0 0 0" />
      <geometry>
        <mesh filename="${meshes_file_direction}/right_wheel_steer_link.stl" scale="0.001 0.001 0.001" />
      </geometry>
    </collision>
    <inertial>
       <origin xyz="9.802728600e-03 5.471240900e-02 -1.376533400e-01" />
       <mass value="7.550951000e-01" />
       <inertia ixx="2.797322900e-03" ixy="3.290833300e-05" ixz="-1.950642500e-04"
       iyy="3.582262300e-03" iyz="2.853288400e-04"
       izz="1.683595100e-03" />
    </inertial>
  </link>
  <joint name="$(arg prefix)right_wheel_drive" type="continuous">
      <parent link="$(arg prefix)right_wheel_steer_link"/>
      <child link="$(arg prefix)right_wheel_drive_link"/>
      <origin xyz="0 0 -0.18905" rpy="0 0 0"/>
      <axis xyz="0 1 0" />
      <limit velocity="9999.0" effort="9999.0"/>
  </joint>
  <link name="$(arg prefix)right_wheel_drive_link">
    <visual>
      <origin xyz="0 0 0" rpy="0 0 0" />
      <geometry>
        <mesh filename="${meshes_file_direction}/right_wheel_drive_link.stl" scale="0.001 0.001 0.001" />
      </geometry>
      <material name="silver">
        <color rgba="0.75 0.75 0.75 1"/>
      </material>
    </visual>
    <collision>
      <origin xyz="0 0 0" rpy="0 0 0" />
      <geometry>
        <mesh filename="${meshes_file_direction}/right_wheel_drive_link.stl" scale="0.001 0.001 0.001" />
      </geometry>
    </collision>
    <inertial>
       <origin xyz="0.000000000e+00 1.499601700e-03 0.000000000e+00" />
       <mass value="3.795460500e+00" />
       <inertia ixx="7.187881500e-03" ixy="0.000000000e+00" ixz="0.000000000e+00"
       iyy="1.156399900e-02" iyz="0.000000000e+00"
       izz="7.187977000e-03" />
    </inertial>
  </link>

  <joint name="$(arg prefix)rear_wheel_steer" type="revolute">
      <parent link="$(arg prefix)base_link"/>
      <child link="$(arg prefix)rear_wheel_steer_link"/>
      <origin xyz="-0.2899 0 0.27555" rpy="0 0 0"/>
      <axis xyz="0 0 1" />
      <limit velocity="9999.0" effort="9999.0" lower="${-pi*6.0}" upper="${pi*6.0}" />
  </joint>
  <link name="$(arg prefix)rear_wheel_steer_link">
    <visual>
      <origin xyz="0 0 0" rpy="0 0 0" />
      <geometry>
        <mesh filename="${meshes_file_direction}/rear_wheel_steer_link.stl" scale="0.001 0.001 0.001" />
      </geometry>
      <material name="silver">
        <color rgba="0.75 0.75 0.75 1"/>
      </material>
    </visual>
    <collision>
      <origin xyz="0 0 0" rpy="0 0 0" />
      <geometry>
        <mesh filename="${meshes_file_direction}/rear_wheel_steer_link.stl" scale="0.001 0.001 0.001" />
      </geometry>
    </collision>
    <inertial>
       <origin xyz="9.802728600e-03 5.471240900e-02 -1.376533400e-01" />
       <mass value="7.550951000e-01" />
       <inertia ixx="2.797322900e-03" ixy="3.290833300e-05" ixz="-1.950642500e-04"
       iyy="3.582262300e-03" iyz="2.853288400e-04"
       izz="1.683595100e-03" />
    </inertial>
  </link>
  <joint name="$(arg prefix)rear_wheel_drive" type="continuous">
      <parent link="$(arg prefix)rear_wheel_steer_link"/>
      <child link="$(arg prefix)rear_wheel_drive_link"/>
      <origin xyz="0 0 -0.18905" rpy="0 0 0"/>
      <axis xyz="0 1 0" />
      <limit velocity="9999.0" effort="9999.0"/>
  </joint>
  <link name="$(arg prefix)rear_wheel_drive_link">
    <visual>
      <origin xyz="0 0 0" rpy="0 0 0" />
      <geometry>
        <mesh filename="${meshes_file_direction}/rear_wheel_drive_link.stl" scale="0.001 0.001 0.001" />
      </geometry>
      <material name="silver">
        <color rgba="0.75 0.75 0.75 1"/>
      </material>
    </visual>
    <collision>
      <origin xyz="0 0 0" rpy="0 0 0" />
      <geometry>
        <mesh filename="${meshes_file_direction}/rear_wheel_drive_link.stl" scale="0.001 0.001 0.001" />
      </geometry>
    </collision>
    <inertial>
       <origin xyz="0.000000000e+00 1.499601700e-03 0.000000000e+00" />
       <mass value="3.795460500e+00" />
       <inertia ixx="7.187881500e-03" ixy="0.000000000e+00" ixz="0.000000000e+00"
       iyy="1.156399900e-02" iyz="0.000000000e+00"
       izz="7.187977000e-03" />
    </inertial>
  </link>

  <xacro:ffw_sg2_follower_system
    use_sim="$(arg use_sim)"
    use_fake_hardware="$(arg use_fake_hardware)"
    fake_sensor_commands="$(arg fake_sensor_commands)"/>

  <xacro:ffw_sg2_base_system
    use_sim="$(arg use_sim)"
    use_fake_hardware="$(arg use_fake_hardware)"
    fake_sensor_commands="$(arg fake_sensor_commands)"/>

  <xacro:ffw_sg2_sensor_system
    use_sim="$(arg use_sim)"
    use_fake_hardware="$(arg use_fake_hardware)"
    fake_sensor_commands="$(arg fake_sensor_commands)"/>

  <gazebo>
      <plugin filename="gz_ros2_control-system" name="gz_ros2_control::GazeboSimROS2ControlPlugin">
        <parameters>$(find ffw_bringup)/config/$(arg model)/ffw_sg2_follower_ai_hardware_controller.yaml</parameters>
      </plugin>
  </gazebo>

</robot>
